Workbook

Sheet Lists
A1: Not Started | B1: Must Have | C1: Functional | D1: Foundation | E1: superadmin
A2: In Progress | B2: Should Have | C2: Non-Functional | D2: Core Build | E2: admin
A3: Blocked | B3: Could Have | C3: Data | D3: Admin & Security | E3: manager
A4: Done | C4: Security | D4: Hardening | E4: user
C5: UX | D5: Release

Sheet README
A1: Python Desktop Application - SRS and Delivery Plan
A3: Prepared For | B3: Desktop application with PostgreSQL + Liquibase, authentication, RBAC, and future extensibility
A4: Assumed Project Start (editable) | B4: 46119
A5: Recommended UI Stack | B5: PySide6 (Qt for Python) for a professional native desktop UI
A6: Migration Strategy | B6: Liquibase changelogs managed separately from Python application code
A7: Architecture Style | B7: Modular layered architecture: presentation, application, domain, infrastructure
A9: Project Snapshot
A10: Total requirements | B10: =COUNTA(Requirements!A4:A24) -> 21
A11: Functional requirements | B11: =COUNTIF(Requirements!B4:B24,"Functional") -> 14
A12: Non-functional/data/security/ux requirements | B12: =B10-B11 -> 7
A13: Total milestones | B13: =COUNTA(Milestones!A4:A9) -> 6
A14: Total planned tasks | B14: =COUNTA(Plan!A4:A25) -> 22
A15: Total planned effort (days) | B15: =SUM(Plan!D4:D25) -> 35
A16: Projected finish date | B16: =MAX(Plan!G4:G25) -> 46153
A17: Total AI prompts prepared | B17: =COUNTA(Prompts!A4:A19) -> 16
A20: How to Use This Workbook
A21: • | B21: Requirements sheet captures functional and non-functional expectations with acceptance criteria.
A22: • | B22: Roles_Permissions defines the baseline RBAC model and the suggested permission catalog.
A23: • | B23: DB_Schema provides a normalized PostgreSQL schema designed for future feature growth.
A24: • | B24: Liquibase_Plan organizes the initial database migrations and rollback expectations.
A25: • | B25: Milestones and Plan provide a practical implementation roadmap; change the project start on this sheet if needed.
A26: • | B26: Prompts contains copy/paste prompts for incremental development tasks.

Sheet SRS
A1: Software Requirements Specification
A3: 1. Purpose | B3: Build a maintainable desktop application in Python with a professional user interface, PostgreSQL persistence, Liquibase-based schema versioning, secure login using username or mobile number with password, and a configurable role-based access control model.
A4: 2. In Scope | B4: Authentication, user administration, role and permission management, normalized database design, auditability, future-ready modular architecture, and planning for incremental delivery.
A5: 3. Out of Scope (initial release) | B5: Advanced SSO, biometric login, multi-tenant isolation, external identity providers, fine-grained field masking, reporting warehouse, and mobile app support.
A6: 4. Primary Actors | B6: Superadmin, Admin, Manager, End User, Support/Operations.
A7: 5. Business Goals | B7: Secure application access, delegated administration, controlled feature access through RBAC, easy future extension, and a polished desktop user experience.
A8: 6. Recommended Technical Stack | B8: UI: PySide6. Backend/application layer: Python 3.11+ service modules. ORM/data access: SQLAlchemy 2.x. Database: PostgreSQL 15+. Migrations: Liquibase XML/YAML/SQL changelogs. Packaging: PyInstaller or Briefcase.
A9: 7. Security Expectations | B9: Passwords stored as strong salted hashes (Argon2id or bcrypt), account lockout policy, password change tracking, audit logging, and secure secret handling outside source control.
A10: 8. Extensibility Expectations | B10: Use modular packages, configuration-driven permissions, additive Liquibase changesets, and service interfaces so new modules can be plugged in later without redesigning the core schema.
A11: 9. Usability Expectations | B11: Responsive forms, clear error messages, keyboard-friendly data entry, role-aware navigation, and consistent visual styling across screens.
A12: 10. Success Criteria | B12: Users can authenticate by username or mobile, admins can create/update roles and permissions, permissions are enforced in the UI and backend, schema is migration-controlled, and the codebase can accommodate new business modules.
A14: Suggested Application Modules
A15: Module | B15: Responsibility
A16: Presentation | B16: Desktop screens, dialogs, forms, dashboards, validation feedback
A17: Application | B17: Use cases, workflows, RBAC checks, orchestration services
A18: Domain | B18: User, Role, Permission, Audit, Session, Settings rules
A19: Infrastructure | B19: PostgreSQL repositories, Liquibase execution, logging, packaging
A20: Security | B20: Password hashing, lockout, session lifecycle, permission guards
A21: Administration | B21: User management, role management, permission catalog management

Sheet Requirements
A1: Requirements Register
A3: Req ID | B3: Type | C3: Module | D3: Requirement | E3: Acceptance Criteria | F3: Priority | G3: Phase | H3: Notes
A4: FR-01 | B4: Functional | C4: Authentication | D4: User can log in with either username or registered mobile number plus password. | E4: Login succeeds when valid identifier/password pair is provided; invalid attempts show safe error message. | F4: Must Have | G4: Foundation | H4: Support multiple identifier types through normalized login_identifiers table.
A5: FR-02 | B5: Functional | C5: Authentication | D5: System must validate account status before login. | E5: Inactive, locked, or disabled accounts cannot access the application. | F5: Must Have | G5: Foundation | H5: Supports security control and admin actions.
A6: FR-03 | B6: Functional | C6: Security | D6: Passwords must be stored as salted secure hashes. | E6: No plain-text password is stored anywhere in database or logs. | F6: Must Have | G6: Foundation | H6: Use Argon2id or bcrypt.
A7: FR-04 | B7: Functional | C7: Authorization | D7: System must support configurable roles such as superadmin, admin, manager, and user. | E7: Default roles exist at setup and can be assigned to users. | F7: Must Have | G7: Foundation | H7: Roles should be data-driven.
A8: FR-05 | B8: Functional | C8: Authorization | D8: Permissions must be assignable to roles and enforced by the application. | E8: Access to screens/actions is blocked when required permission is missing. | F8: Must Have | G8: Core Build | H8: RBAC must be checked in UI and service layer.
A9: FR-06 | B9: Functional | C9: Administration | D9: Authorized admins can create, update, activate, and deactivate users. | E9: Changes are persisted and visible in user management screens. | F9: Must Have | G9: Core Build | H9: Soft delete preferred for auditability.
A10: FR-07 | B10: Functional | C10: Administration | D10: Authorized admins can create, update, activate, and deactivate roles. | E10: Role changes are reflected immediately in access rules after assignment. | F10: Must Have | G10: Core Build | H10: Protect system roles from unsafe deletion.
A11: FR-08 | B11: Functional | C11: Administration | D11: Authorized admins can create and modify permission definitions. | E11: New permissions can be added without changing core user table structure. | F11: Should Have | G11: Core Build | H11: Catalog management may be admin-only.
A12: FR-09 | B12: Functional | C12: Administration | D12: Authorized admins can map permissions to roles. | E12: Role-permission assignments can be added or removed through UI. | F12: Must Have | G12: Core Build | H12: Store in role_permissions junction table.
A13: FR-10 | B13: Functional | C13: Administration | D13: Authorized admins can assign multiple roles to a single user. | E13: A user can inherit permissions from all assigned active roles. | F13: Should Have | G13: Core Build | H13: Many-to-many user_roles table.
A14: FR-11 | B14: Functional | C14: Audit | D14: System must record key administrative and authentication events. | E14: Login success/failure, user changes, role changes, and permission changes are logged. | F14: Must Have | G14: Admin & Security | H14: Store summary and before/after JSON where appropriate.
... A24: NFR-07 | B24: UX | C24: Accessibility | D24: Forms and navigation should support keyboard usage and readable typography. | E24: Primary workflows can be executed with keyboard-only navigation. | F24: Could Have | G24: Hardening | H24: Improves desktop productivity.

Sheet Roles_Permissions
A1: RBAC Model - Roles and Permissions
A3: Default Roles
A4: Role | B4: Purpose | C4: Can Manage Users | D4: Can Manage Roles/Permissions | E4: Notes
A5: superadmin | B5: Full system administration and recovery actions | C5: Yes | D5: Yes | E5: System-level role; should be protected from accidental deactivation.
A6: admin | B6: Operational administration and day-to-day configuration | C6: Yes | D6: Yes | E6: Can manage users and business roles under policy.
A7: manager | B7: Business supervision with limited administrative rights | C7: Limited | D7: No | E7: Typically manages business operations and approvals.
A8: user | B8: Standard application user | C8: No | D8: No | E8: Access only to assigned business functions.
A10: Suggested Permission Catalog and Default Assignment
A11: Permission Code | B11: Business Meaning | C11: Module | D11: superadmin | E11: admin | F11: manager | G11: user | H11: Priority | I11: Notes
A12: auth.login | B12: Access application login flow | C12: Authentication | D12: Y | E12: Y | F12: Y | G12: Y | H12: Must Have | I12: Granted to all active users.
A13: user.view | B13: View user list and profile details | C13: Administration | D13: Y | E13: Y | F13: N | G13: N | H13: Must Have | I13: Admin area visibility.
A14: user.create | B14: Create a user account | C14: Administration | D14: Y | E14: Y | F14: N | G14: N | H14: Must Have | I14: Create flow.
A15: user.update | B15: Edit user account profile/status | C15: Administration | D15: Y | E15: Y | F15: N | G15: N | H15: Must Have | I15: Includes activation/deactivation.
A16: user.assignRoles | B16: Assign roles to users | C16: Administration | D16: Y | E16: Y | F16: N | G16: N | H16: Must Have | I16: Critical RBAC control.
A17: role.view | B17: View roles and mappings | C17: Administration | D17: Y | E17: Y | F17: N | G17: N | H17: Must Have | I17: Role catalog read.
A18: role.create | B18: Create a role | C18: Administration | D18: Y | E18: Y | F18: N | G18: N | H18: Should Have | I18: Data-driven role management.
A19: role.update | B19: Modify role definition | C19: Administration | D19: Y | E19: Y | F19: N | G19: N | H19: Must Have | I19: Should block unsafe system-role changes.
A20: role.delete | B20: Deactivate or remove a non-system role | C20: Administration | D20: Y | E20: Limited | F20: N | G20: N | H20: Could Have | I20: Prefer deactivate over hard delete.
A21: permission.view | B21: View permission catalog | C21: Administration | D21: Y | E21: Y | F21: N | G21: N | H21: Must Have | I21: Supports audits.
A22: permission.create | B22: Create permission definitions | C22: Administration | D22: Y | E22: Limited | F22: N | G22: N | H22: Should Have | I22: Often reserved for higher admins.
... A26: settings.manage | B26: Manage application settings | C26: Configuration | D26: Y | E26: Limited | F26: N | G26: N | H26: Could Have | I26: Useful for future features.

Sheet DB_Schema
A1: Normalized PostgreSQL Schema (3NF-oriented)
A3: Table | B3: Column | C3: Data Type | D3: PK | E3: FK | F3: Unique | G3: Null? | H3: Default | I3: Purpose / Rule | J3: Relationship Notes
A4: users | B4: user_id | C4: BIGSERIAL | D4: Y | F4: Y | G4: N | I4: Surrogate primary key | J4: Parent table for identities, roles, audit
A5: users | B5: first_name | C5: VARCHAR(100) | G5: N | I5: User given name
A6: users | B6: last_name | C6: VARCHAR(100) | G6: Y | I6: User family name
A7: users | B7: display_name | C7: VARCHAR(150) | G7: Y | I7: Friendly UI name
A8: users | B8: status | C8: VARCHAR(20) | G8: N | H8: 'ACTIVE' | I8: ACTIVE/INACTIVE/LOCKED
A9: users | B9: created_at | C9: TIMESTAMP | G9: N | H9: now() | I9: Audit timestamp
A10: users | B10: updated_at | C10: TIMESTAMP | G10: N | H10: now() | I10: Audit timestamp
A11: login_identifiers | B11: identifier_id | C11: BIGSERIAL | D11: Y | F11: Y | G11: N | I11: PK for login identifiers | J11: Child of users (1-to-many)
A12: login_identifiers | B12: user_id | C12: BIGINT | E12: users.user_id | G12: N | I12: Owner user | J12: Many identifiers per user
A13: login_identifiers | B13: identifier_type | C13: VARCHAR(20) | G13: N | I13: USERNAME / MOBILE
A14: login_identifiers | B14: identifier_value | C14: VARCHAR(150) | G14: N | I14: Original value entered by admin/user
A15: login_identifiers | B15: normalized_value | C15: VARCHAR(150) | F15: Y | G15: N | I15: Case/format normalized lookup value | J15: Unique login key across system
A16: login_identifiers | B16: is_primary | C16: BOOLEAN | G16: N | H16: false | I16: Preferred login/display identifier
A17: login_identifiers | B17: is_verified | C17: BOOLEAN | G17: N | H17: false | I17: Supports future OTP/verification flows
A18: auth_credentials | B18: credential_id | C18: BIGSERIAL | D18: Y | F18: Y | G18: N | I18: PK for auth record | J18: 1-to-1 with users
A19: auth_credentials | B19: user_id | C19: BIGINT | E19: users.user_id | F19: Y | G19: N | I19: One credential record per user
A20: auth_credentials | B20: password_hash | C20: VARCHAR(255) | G20: N | I20: Salted password hash only
A21: auth_credentials | B21: password_algo | C21: VARCHAR(30) | G21: N | H21: 'argon2id' | I21: Hash algorithm marker
A22: auth_credentials | B22: password_changed_at | C22: TIMESTAMP | G22: Y | I22: Password lifecycle audit
A23: auth_credentials | B23: failed_attempt_count | C23: INT | G23: N | H23: 0 | I23: Support lockout logic
A24: auth_credentials | B24: locked_until | C24: TIMESTAMP | G24: Y | I24: Temporary lock expiration
A25: auth_credentials | B25: last_login_at | C25: TIMESTAMP | G25: Y | I25: User last successful login
A26: roles | B26: role_id | C26: BIGSERIAL | D26: Y | F26: Y | G26: N | I26: PK for roles | J26: Parent table for user_roles and role_permissions
A27: roles | B27: role_code | C27: VARCHAR(50) | F27: Y | G27: N | I27: Stable code, e.g. ADMIN
A28: roles | B28: role_name | C28: VARCHAR(100) | G28: N | I28: Display label
A29: roles | B29: description | C29: TEXT | G29: Y | I29: Business meaning
A30: roles | B30: is_system_role | C30: BOOLEAN | G30: N | H30: false | I30: Protect built-in roles
A31: roles | B31: is_active | C31: BOOLEAN | G31: N | H31: true | I31: Soft lifecycle
A32: permissions | B32: permission_id | C32: BIGSERIAL | D32: Y | F32: Y | G32: N | I32: PK for permissions | J32: Parent for role_permissions
A33: permissions | B33: permission_code | C33: VARCHAR(100) | F33: Y | G33: N | I33: Stable code, e.g. user.create
A34: permissions | B34: module_name | C34: VARCHAR(100) | G34: N | I34: Functional grouping
A35: permissions | B35: action_name | C35: VARCHAR(100) | G35: N | I35: View/Create/Update/Delete/etc.
A36: permissions | B36: description | C36: TEXT | G36: Y | I36: Business meaning
A37: permissions | B37: is_active | C37: BOOLEAN | G37: N | H37: true | I37: Soft lifecycle
A38: user_roles | B38: user_role_id | C38: BIGSERIAL | D38: Y | F38: Y | G38: N | I38: Surrogate PK | J38: Junction table users ↔ roles
A39: user_roles | B39: user_id | C39: BIGINT | E39: users.user_id | G39: N | I39: Assigned user
A40: user_roles | B40: role_id | C40: BIGINT | E40: roles.role_id | G40: N | I40: Assigned role
A41: user_roles | B41: assigned_by | C41: BIGINT | E41: users.user_id | G41: Y | I41: Admin who assigned role
...

Sheet Liquibase_Plan
A1: Liquibase Migration Plan
A3: Order | B3: ChangeSet ID | C3: Change Type | D3: Objects | E3: Purpose | F3: Rollback Strategy | G3: Notes
A4: 1 | B4: 001-create-core-users | C4: createTable | D4: users | E4: Create base user master table | F4: dropTable users | G4: Establishes identity root.
A5: 2 | B5: 002-create-login-identifiers | C5: createTable | D5: login_identifiers | E5: Support username/mobile login identifiers | F5: dropTable login_identifiers | G5: Add unique index on normalized_value.
A6: 3 | B6: 003-create-auth-credentials | C6: createTable | D6: auth_credentials | E6: Store password hash and lockout metadata | F6: dropTable auth_credentials | G6: Separate credentials from profile.
A7: 4 | B7: 004-create-roles | C7: createTable + loadData | D7: roles | E7: Create role master and seed default roles | F7: delete seed rows / dropTable | G7: Seed superadmin, admin, manager, user.
A8: 5 | B8: 005-create-permissions | C8: createTable + loadData | D8: permissions | E8: Create permission catalog and seed baseline permissions | F8: delete seed rows / dropTable | G8: Seed only core permissions first.
A9: 6 | B9: 006-create-user-roles | C9: createTable | D9: user_roles | E9: Map users to roles | F9: dropTable user_roles | G9: Add unique composite rule.
A10: 7 | B10: 007-create-role-permissions | C10: createTable | D10: role_permissions | E10: Map roles to permissions | F10: dropTable role_permissions | G10: Central RBAC mapping.
A11: 8 | B11: 008-create-user-sessions | C11: createTable | D11: user_sessions | E11: Track login sessions | F11: dropTable user_sessions | G11: Optional in first release; can still be included.
A12: 9 | B12: 009-create-audit-logs | C12: createTable | D12: audit_logs | E12: Track security and admin events | F12: dropTable audit_logs | G12: Use JSONB snapshots for before/after.
A13: 10 | B13: 010-create-app-settings | C13: createTable | D13: app_settings | E13: Store future-ready config items | F13: dropTable app_settings | G13: Supports extensibility without redesign.
A14: 11 | B14: 011-add-indexes | C14: createIndex | D14: login_identifiers, user_roles, role_permissions, audit_logs | E14: Improve lookup and enforcement performance | F14: dropIndex | G14: Index normalized_value and FK columns.
A15: 12 | B15: 012-add-constraints | C15: addForeignKeyConstraint / addUniqueConstraint | D15: core RBAC tables | E15: Enforce relational integrity | F15: drop constraints | G15: Keep schema consistent across environments.

Sheet Milestones
A1: Milestones
A3: Milestone ID | B3: Milestone | C3: Goal | D3: Start Date | E3: Duration (days) | F3: End Date | G3: Exit Criteria
A4: M1 | B4: Foundation & Architecture | C4: Finalize stack, project structure, security baseline, and schema design | D4: 46119 | E4: 5 | F4: =D4+E4-1 -> 46123 | G4: Architecture approved; schema and SRS signed off.
A5: M2 | B5: Database & Migration Baseline | C5: Implement PostgreSQL schema and Liquibase changelogs | D5: 46124 | E5: 5 | F5: =D5+E5-1 -> 46128 | G5: Liquibase baseline runs clean on local and test DB.
A6: M3 | B6: Authentication Module | C6: Deliver login with username/mobile and secure credential flow | D6: 46129 | E6: 6 | F6: =D6+E6-1 -> 46134 | G6: Login flow works with validation and lockout basics.
A7: M4 | B7: RBAC & Admin Module | C7: Deliver role, permission, and user-role management | D7: 46135 | E7: 8 | F7: =D7+E7-1 -> 46142 | G7: Admins can manage roles/permissions and user assignments.
A8: M5 | B8: Audit, Hardening & UX Polish | C8: Add audit trail, error handling, and UI polish | D8: 46143 | E8: 6 | F8: =D8+E8-1 -> 46148 | G8: Audit log and user-friendly validation are completed.
A9: M6 | B9: Testing, Packaging & Release Prep | C9: Stabilize, test, package, and document the release | D9: 46149 | E9: 5 | F9: =D9+E9-1 -> 46153 | G9: Acceptance tests passed and desktop package generated.

Sheet Plan
A1: Detailed Implementation Plan
A3: Task ID | B3: Milestone | C3: Task | D3: Effort (days) | E3: Owner | F3: Planned Start | G3: Planned End | H3: Dependency | I3: Deliverable | J3: Status
A4: T01 | B4: M1 | C4: Finalize architecture, stack, coding standards, and repository layout | D4: 1 | E4: Architect | F4: =README!$B$4 -> 46119 | G4: =F4+D4-1 -> 46119 | H4: - | I4: Approved architecture note | J4: Not Started
A5: T02 | B5: M1 | C5: Prepare SRS, screen list, and data flow decisions | D5: 1 | E5: BA/Architect | F5: =G4+1 -> 46120 | G5: =F5+D5-1 -> 46120 | H5: T01 | I5: Approved SRS and flow summary | J5: Not Started
A6: T03 | B6: M1 | C6: Design normalized PostgreSQL schema and RBAC model | D6: 2 | E6: DB Engineer | F6: =G5+1 -> 46121 | G6: =F6+D6-1 -> 46122 | H6: T02 | I6: Reviewed ERD/schema specification | J6: Not Started
A7: T04 | B7: M1 | C7: Set up project scaffold with modular folders and environment config | D7: 1 | E7: Python Dev | F7: =G6+1 -> 46123 | G7: =F7+D7-1 -> 46123 | H7: T01 | I7: Working starter project | J7: Not Started
A8: T05 | B8: M2 | C8: Create Liquibase master changelog and baseline changesets | D8: 2 | E8: DB Engineer | F8: =G7+1 -> 46124 | G8: =F8+D8-1 -> 46125 | H8: T03 | I8: Baseline changelog files | J8: Not Started
A9: T06 | B9: M2 | C9: Provision PostgreSQL local/test environments and validate migrations | D9: 1 | E9: DevOps/DBA | F9: =G8+1 -> 46126 | G9: =F9+D9-1 -> 46126 | H9: T05 | I9: Database bootstrap script | J9: Not Started
A10: T07 | B10: M2 | C10: Implement ORM models and repository interfaces | D10: 2 | E10: Python Dev | F10: =G9+1 -> 46127 | G10: =F10+D10-1 -> 46128 | H10: T05 | I10: Data access layer | J10: Not Started
A11: T08 | B11: M3 | C11: Build login screen with username/mobile identifier input | D11: 1 | E11: UI Dev | F11: =G10+1 -> 46129 | G11: =F11+D11-1 -> 46129 | H11: T04 | I11: Desktop login UI | J11: Not Started
A12: T09 | B12: M3 | C12: Implement authentication service and password verification | D12: 2 | E12: Python Dev | F12: =G11+1 -> 46130 | G12: =F12+D12-1 -> 46131 | H12: T07 | I12: Auth service | J12: Not Started
A13: T10 | B13: M3 | C13: Add lockout, failed-attempt tracking, and secure session start | D13: 2 | E13: Python Dev | F13: =G12+1 -> 46132 | G13: =F13+D13-1 -> 46133 | H13: T09 | I13: Security controls | J13: Not Started
A14: T11 | B14: M3 | C14: Wire login UI to backend and database | D14: 1 | E14: Full-stack Dev | F14: =G13+1 -> 46134 | G14: =F14+D14-1 -> 46134 | H14: T08,T09 | I14: End-to-end login flow | J14: Not Started
A15: T12 | B15: M4 | C15: Create user management screens and CRUD workflows | D15: 2 | E15: UI/Backend Dev | F15: =G14+1 -> 46135 | G15: =F15+D15-1 -> 46136 | H15: T07 | I15: User administration feature | J15: Not Started
A16: T13 | B16: M4 | C16: Create role management screens and service layer | D16: 2 | E16: UI/Backend Dev | F16: =G15+1 -> 46137 | G16: =F16+D16-1 -> 46138 | H16: T07 | I16: Role administration feature | J16: Not Started
... A25: T22 | B25: M6 | C25: Prepare handover guide, admin manual, and release notes | D25: 1 | E25: BA/QA | F25: =G24+1 -> 46153 | G25: =F25+D25-1 -> 46153 | H25: T21 | I25: Release documentation | J25: Not Started

Sheet Prompts
A1: Incremental Development Prompts
A3: Prompt ID | B3: Phase | C3: Goal | D3: Copy/Paste Prompt | E3: Expected Output | F3: Dependency
A4: P01 | B4: Foundation | C4: Architecture and folder structure | D4: Act as a senior Python desktop architect. Design a modular desktop application using PySide6, PostgreSQL, and Liquibase. Propose a clean folder structure with presentation, application, domain, infrastructure, and tests. Include configuration strategy, dependency boundaries, and packaging considerations for future extensibility. | E4: Architecture note, folder structure, module responsibilities, bootstrap guidance | F4: -
A5: P02 | B5: Foundation | C5: Screen map and UX baseline | D5: Act as a desktop UX engineer. Define the complete screen list for an authentication + RBAC administration app in PySide6. Include login, dashboard, user management, role management, permission management, and audit log screens. For each screen, describe layout, key widgets, validation feedback, and navigation flow. | E5: Screen inventory and UX specification | F5: P01
A6: P03 | B6: Foundation | C6: Normalized PostgreSQL schema | D6: Design a normalized PostgreSQL schema for a desktop application that supports login by username or mobile number, secure password storage, multiple roles per user, configurable permissions, audit logs, sessions, and future extensibility. Provide tables, columns, PK/FK, unique constraints, indexes, and a relationship explanation. | E6: DDL-ready schema design and ERD-style explanation | F6: P01
A7: P04 | B7: Foundation | C7: Liquibase changelog baseline | D7: Generate a Liquibase migration plan and sample changelog structure for the RBAC desktop application schema. Organize changesets for users, login identifiers, credentials, roles, permissions, user-role mapping, role-permission mapping, sessions, audit logs, and settings. Include rollback guidance. | E7: Liquibase changelog plan with ordered changesets | F7: P03
A8: P05 | B8: Core Build | C8: Project scaffold and bootstrap | D8: Create a Python project scaffold for the desktop application. Use PySide6 for UI, SQLAlchemy for data access, and configuration files/environment variables for runtime settings. Show startup flow, dependency injection approach, and placeholders for Liquibase execution before app startup. | E8: Starter project files and bootstrap code | F8: P01,P04
A9: P06 | B9: Core Build | C9: Login UI implementation | D9: Build a PySide6 login window for a desktop application where the user can sign in using either username or mobile number and a password. Include polished layout, validation messages, show/hide password, loading state, and clean separation between UI and auth service calls. | E9: Login screen code with reusable widgets | F9: P02,P05
A10: P07 | B10: Core Build | C10: Authentication service | D10: Implement a Python authentication service for PostgreSQL-backed desktop software. Requirements: lookup by normalized username or mobile, verify secure password hash, reject inactive or locked accounts, update last login, increment failed attempts, and support temporary lockout. Provide service code and repository contracts. | E10: Auth service, repository methods, and security flow | F10: P03,P05
A11: P08 | B11: Core Build | C11: Role and permission domain logic | D11: Implement the Python domain and service layer for roles, permissions, user-role assignment, and role-permission mapping. The design must allow new roles and permissions to be added or modified without code changes to core models. Include validation rules and service interfaces. | E11: RBAC service classes and business rules | F11: P03,P05
A12: P09 | B12: Admin & Security | C12: User management module | D12: Create a user management module in PySide6 with create, update, activate, deactivate, and role assignment capabilities. The module must integrate with the RBAC service layer and keep UI logic separate from persistence logic. Include table view, form dialog, and validation guidance. | E12: User admin UI and workflow design/code | F12: P06,P08
A13: P10 | B13: Admin & Security | C13: Role and permission administration UI | D13: Create PySide6 screens for role management and permission mapping. Requirements: list roles, create/update role, view permission catalog, assign/unassign permissions to roles, and protect system roles from unsafe deletion. Provide a maintainable UI architecture and sample code. | E13: Role/permission admin screens and interaction patterns | F13: P08,P09
A14: P11 | B14: Admin & Security | C14: RBAC enforcement | D14: Show how to enforce role-based permissions consistently in a Python desktop application. Include navigation guards, button/action enablement, service-layer authorization checks, and a strategy to keep permission codes centralized and testable. | E14: Permission guard pattern and enforcement examples | F14: P08
... A19: P16 | B19: Future Ready | C19: Extension planning | D19: Propose an extension strategy for the Python desktop application so future modules can be added with minimal rework. Include module registration, settings management, permission expansion, migration discipline, event hooks, and coding standards for future teams. | E19: Future extension blueprint and governance guidance | F19: P01,P08,P12
